import { render, screen, fireEvent } from '@testing-library/react'
import ErrorBoundary from '../../../../../frontend/src/components/ui/ErrorBoundary'

// Component that throws an error for testing
const ThrowError = ({ shouldThrow }: { shouldThrow: boolean }) => {
  if (shouldThrow) {
    throw new Error('Test error')
  }
  return <div>No error</div>
}

describe('ErrorBoundary', () => {
  // Suppress console.error for these tests
  const originalError = console.error
  beforeAll(() => {
    console.error = jest.fn()
  })
  afterAll(() => {
    console.error = originalError
  })

  it('renders children when there is no error', () => {
    render(
      <ErrorBoundary>
        <div>Test content</div>
      </ErrorBoundary>
    )
    
    expect(screen.getByText('Test content')).toBeInTheDocument()
  })

  it('renders error UI when there is an error', () => {
    render(
      <ErrorBoundary>
        <ThrowError shouldThrow={true} />
      </ErrorBoundary>
    )
    
    expect(screen.getByText('Something went wrong')).toBeInTheDocument()
    expect(screen.getByText('We encountered an unexpected error. Please try again.')).toBeInTheDocument()
    expect(screen.getByRole('button', { name: 'Try again' })).toBeInTheDocument()
  })

  it('renders custom fallback when provided', () => {
    const customFallback = <div>Custom error message</div>
    
    render(
      <ErrorBoundary fallback={customFallback}>
        <ThrowError shouldThrow={true} />
      </ErrorBoundary>
    )
    
    expect(screen.getByText('Custom error message')).toBeInTheDocument()
    expect(screen.queryByText('Something went wrong')).not.toBeInTheDocument()
  })

  it('calls onError callback when error occurs', () => {
    const onError = jest.fn()
    
    render(
      <ErrorBoundary onError={onError}>
        <ThrowError shouldThrow={true} />
      </ErrorBoundary>
    )
    
    expect(onError).toHaveBeenCalledWith(
      expect.any(Error),
      expect.objectContaining({
        componentStack: expect.any(String)
      })
    )
  })

  it('resets error state when retry button is clicked', () => {
    const { rerender } = render(
      <ErrorBoundary>
        <ThrowError shouldThrow={true} />
      </ErrorBoundary>
    )
    
    // Error UI should be visible
    expect(screen.getByText('Something went wrong')).toBeInTheDocument()
    
    // Click retry button
    fireEvent.click(screen.getByRole('button', { name: 'Try again' }))
    
    // Re-render with no error
    rerender(
      <ErrorBoundary>
        <ThrowError shouldThrow={false} />
      </ErrorBoundary>
    )
    
    expect(screen.getByText('No error')).toBeInTheDocument()
    expect(screen.queryByText('Something went wrong')).not.toBeInTheDocument()
  })

  it('logs error to console', () => {
    const consoleSpy = jest.spyOn(console, 'error').mockImplementation()
    
    render(
      <ErrorBoundary>
        <ThrowError shouldThrow={true} />
      </ErrorBoundary>
    )
    
    expect(consoleSpy).toHaveBeenCalledWith(
      'ErrorBoundary caught an error:',
      expect.any(Error),
      expect.any(Object)
    )
    
    consoleSpy.mockRestore()
  })
})